Traceback (most recent call last):
  File "/Users/uec/code/mambaforge/lib/python3.10/site-packages/jupyter_cache/executors/utils.py", line 58, in single_nb_execution
    executenb(
  File "/Users/uec/code/mambaforge/lib/python3.10/site-packages/nbclient/client.py", line 1305, in execute
    return NotebookClient(nb=nb, resources=resources, km=km, **kwargs).execute()
  File "/Users/uec/code/mambaforge/lib/python3.10/site-packages/jupyter_core/utils/__init__.py", line 166, in wrapped
    return loop.run_until_complete(inner)
  File "/Users/uec/code/mambaforge/lib/python3.10/asyncio/base_events.py", line 649, in run_until_complete
    return future.result()
  File "/Users/uec/code/mambaforge/lib/python3.10/site-packages/nbclient/client.py", line 705, in async_execute
    await self.async_execute_cell(
  File "/Users/uec/code/mambaforge/lib/python3.10/site-packages/nbclient/client.py", line 1058, in async_execute_cell
    await self._check_raise_for_error(cell, cell_index, exec_reply)
  File "/Users/uec/code/mambaforge/lib/python3.10/site-packages/nbclient/client.py", line 914, in _check_raise_for_error
    raise CellExecutionError.from_cell_and_msg(cell, exec_reply_content)
nbclient.exceptions.CellExecutionError: An error occurred while executing the following cell:
------------------
# load the ATS solution
directory = ""
vis = ats_xdmf.VisFile(directory)
vis.loadMesh(columnar=True)
------------------


[0;31m---------------------------------------------------------------------------[0m
[0;31mRuntimeError[0m                              Traceback (most recent call last)
Cell [0;32mIn[2], line 3[0m
[1;32m      1[0m [38;5;66;03m# load the ATS solution[39;00m
[1;32m      2[0m directory [38;5;241m=[39m [38;5;124m"[39m[38;5;124m"[39m
[0;32m----> 3[0m vis [38;5;241m=[39m [43mats_xdmf[49m[38;5;241;43m.[39;49m[43mVisFile[49m[43m([49m[43mdirectory[49m[43m)[49m
[1;32m      4[0m vis[38;5;241m.[39mloadMesh(columnar[38;5;241m=[39m[38;5;28;01mTrue[39;00m)

File [0;32m/Users/Shared/ornldev/code/ats/ats/repos/master/src/physics/ats/tools/utils/ats_xdmf.py:81[0m, in [0;36mVisFile.__init__[0;34m(self, directory, domain, filename, mesh_filename, time_unit)[0m
[1;32m     79[0m [38;5;28mself[39m[38;5;241m.[39mfname [38;5;241m=[39m os[38;5;241m.[39mpath[38;5;241m.[39mjoin([38;5;28mself[39m[38;5;241m.[39mdirectory, [38;5;28mself[39m[38;5;241m.[39mfilename)
[1;32m     80[0m [38;5;28;01mif[39;00m [38;5;129;01mnot[39;00m os[38;5;241m.[39mpath[38;5;241m.[39misfile([38;5;28mself[39m[38;5;241m.[39mfname):
[0;32m---> 81[0m     [38;5;28;01mraise[39;00m [38;5;167;01mRuntimeError[39;00m([38;5;124m"[39m[38;5;124mCannot load ATS XDMF h5 file at: [39m[38;5;132;01m{}[39;00m[38;5;124m"[39m[38;5;241m.[39mformat([38;5;28mself[39m[38;5;241m.[39mfname))
[1;32m     82[0m [38;5;28mself[39m[38;5;241m.[39md [38;5;241m=[39m h5py[38;5;241m.[39mFile([38;5;28mself[39m[38;5;241m.[39mfname,[38;5;124m'[39m[38;5;124mr[39m[38;5;124m'[39m)
[1;32m     83[0m [38;5;28mself[39m[38;5;241m.[39mloadTimes()

[0;31mRuntimeError[0m: Cannot load ATS XDMF h5 file at: ats_vis_data.h5

